<?xml version="1.0"?>
<robot name="gripper">
    
    <link name="base_frame">
        <visual>
            <origin xyz="-21 -21 6" rpy="0 0 0"/>
            <geometry>
                <mesh filename="/home/daniel/dev/ros2_iiwa7/src/iiwa_description/resource/meshes/gripper/base_frame.stl" />
            </geometry>
        </visual>
        <collision>
            <origin xyz="-21 -21 6" rpy="0 0 0"/>
            <geometry>
                <mesh filename="/home/daniel/dev/ros2_iiwa7/src/iiwa_description/resource/meshes/gripper/base_frame.stl" />
            </geometry>
        </collision>
        <inertial>
            <mass value="0.0"/>
            <origin xyz=" 0.0 0.0 0.0" rpy="0.0 0.0 0.0"/>
            <inertia ixx="0.0" ixy="0.0" ixz="0.0" iyy="0.0" iyz="0.0" izz="0.0"/>
        </inertial>
    </link>

    <link name="plate">
        <visual>
            <geometry>
                <mesh filename="/home/daniel/dev/ros2_iiwa7/src/iiwa_description/resource/meshes/gripper/plate.stl"/>
            </geometry>
        </visual>
        <collision>
            <geometry>
                <mesh filename="/home/daniel/dev/ros2_iiwa7/src/iiwa_description/resource/meshes/gripper/plate.stl"/>
            </geometry>
        </collision>
        <inertial>
            <mass value="0.0"/>
            <origin xyz="0.0 0.0 0.0" rpy="0.0 0.0 0.0"/>
            <inertia ixx="0.0" ixy="0.0" ixz="0.0" iyy="0.0" iyz="0.0" izz="0.0"/>
        </inertial>
    </link>

    <link name="screw">
        <inertial>
            <origin xyz="0.0 0.0 0.0" rpy="0.0 0.0 0.0"/>
            <mass value="0.0"/>
            <inertia ixx="0.0" ixy="0.0" ixz="0.0" iyy="0.0" iyz="0.0" izz="0.0"/>
        </inertial>
        <visual name="">
            <origin xyz="0.0 0.0 0.0" rpy="0.0 0.0 0.0"/>
            <geometry>
                <mesh filename="/home/daniel/dev/ros2_iiwa7/src/iiwa_description/resource/meshes/gripper/screw.stl"/>
            </geometry>
        </visual>
        <collision>
            <origin xyz="0.0 0.0 0.0" rpy="0.0 0.0 0.0"/>
            <geometry>
                <mesh filename="/home/daniel/dev/ros2_iiwa7/src/iiwa_description/resource/meshes/gripper/screw.stl"/>
            </geometry>
        </collision>
    </link>

    <link name="craving1">
        <inertial>
            <origin xyz="0.0 0.0 0" rpy="0.0 0.0 0.0"/>
            <mass value="0.0"/>
            <inertia ixx="0.0" ixy="0.0" ixz="0.0" iyy="0.0" iyz="0.0" izz="0.0"/>
        </inertial>
        <visual name="">
            <origin xyz="-4 -7 19" rpy="0.0 1.57 0"/>
            <geometry>
                <mesh filename="/home/daniel/dev/ros2_iiwa7/src/iiwa_description/resource/meshes/gripper/craving.stl"/>
            </geometry>
        </visual>
        <collision>
            <origin xyz="-4 -7 19" rpy="0.0 1.57 0"/>
            <geometry>
                <mesh filename="/home/daniel/dev/ros2_iiwa7/src/iiwa_description/resource/meshes/gripper/craving.stl"/>
            </geometry>
        </collision>
    </link>

    <link name="craving2">
        <inertial>
            <origin xyz="0.0 0.0 0" rpy="0.0 0.0 0.0"/>
            <mass value="0.0"/>
            <inertia ixx="0.0" ixy="0.0" ixz="0.0" iyy="0.0" iyz="0.0" izz="0.0"/>
        </inertial>
        <visual name="">
            <origin xyz="-4 -7 19" rpy="0.0 1.57 0"/>
            <geometry>
                <mesh filename="/home/daniel/dev/ros2_iiwa7/src/iiwa_description/resource/meshes/gripper/craving.stl"/>
            </geometry>
        </visual>
        <collision>
            <origin xyz="-4 -7 19" rpy="0.0 1.57 0"/>
            <geometry>
                <mesh filename="/home/daniel/dev/ros2_iiwa7/src/iiwa_description/resource/meshes/gripper/craving.stl"/>
            </geometry>
        </collision>
    </link>

    <link name="craving3">
        <inertial>
            <origin xyz="0.0 0.0 0" rpy="0.0 0.0 0.0"/>
            <mass value="0.0"/>
            <inertia ixx="0.0" ixy="0.0" ixz="0.0" iyy="0.0" iyz="0.0" izz="0.0"/>
        </inertial>
        <visual name="">
            <origin xyz="-4 -7 19" rpy="0.0 1.57 0"/>
            <geometry>
                <mesh filename="/home/daniel/dev/ros2_iiwa7/src/iiwa_description/resource/meshes/gripper/craving.stl"/>
            </geometry>
        </visual>
        <collision>
            <origin xyz="-4 -7 19" rpy="0.0 1.57 0"/>
            <geometry>
                <mesh filename="/home/daniel/dev/ros2_iiwa7/src/iiwa_description/resource/meshes/gripper/craving.stl"/>
            </geometry>
        </collision>
    </link>

    <joint name="base" type="fixed">
        <origin xyz="0.0 0.0 61" rpy="0.0 0.0 0.0"/>
        <parent link="base_frame"/>
        <child link="plate"/>
    </joint>

    <joint name="base_screw" type="prismatic">
        <origin xyz="0.0 0.0 72" rpy="0.0 0.0 0.0"/>
        <parent link="base_frame"/>
        <child link="screw"/>
        <axis xyz="0.0 0.0 1"/>
        <limit lower="-7" upper="0.0" effort="0.0" velocity="0.0"/>
    </joint>

    <joint name="craving1_joint" type="revolute">
        <origin xyz="15.5 -9.5 4" rpy="0.0 0 -0.55"/> 
        <parent link="screw"/>
        <child link="craving1"/>
        <axis xyz="0.0 1 0.0"/>
        <limit lower="-0.3" upper="0.2" effort="5.0" velocity="1.0"/>
        <dynamics damping="0.05" friction="0.05"/>
        <mimic joint="base_screw" multiplier="0.07" offset="0.2"/>
    </joint>

    <joint name="craving2_joint" type="revolute">
        <origin xyz="-15.5 -9.5 4" rpy="0.0 0 0.55"/> 
        <parent link="screw"/>
        <child link="craving2"/>
        <axis xyz="0.0 1 0.0"/>
        <limit lower="-0.2" upper="0.3" effort="5.0" velocity="1.0"/>
        <dynamics damping="0.05" friction="0.05"/>
        <mimic joint="base_screw" multiplier="-0.07" offset="-0.2"/>
    </joint>

    <joint name="craving3_joint" type="revolute">
        <origin xyz="0 18 4" rpy="0.0 0 1.57"/> 
        <parent link="screw"/>
        <child link="craving3"/>
        <axis xyz="0.0 1 0.0"/>
        <limit lower="-0.3" upper="0.2" effort="5.0" velocity="1.0"/>
        <dynamics damping="0.05" friction="0.05"/>
        <mimic joint="base_screw" multiplier="0.07" offset="0.2"/>
    </joint>


</robot>
