<?xml version="1.0"?>
<robot name="gripper">
    
    <link name="base_frame">
        <visual>
            <origin xyz="-21 -21 6" rpy="0 0 0"/>
            <geometry>
                <mesh filename="/home/daniel/dev/kuka_iiwa7_ros2/src/iiwa_description/resource/meshes/gripper/base_frame.stl" />
            </geometry>
            <material name="black_plastic">
                <color rgba="0.05 0.05 0.05 1.0"/>
            </material>
        </visual>
        <collision>
            <origin xyz="-21 -21 6" rpy="0 0 0"/>
            <geometry>
                <mesh filename="/home/daniel/dev/kuka_iiwa7_ros2/src/iiwa_description/resource/meshes/gripper/base_frame.stl" />
            </geometry>
        </collision>
        <inertial>
            <mass value="0.0"/>
            <origin xyz=" 0.0 0.0 0.0" rpy="0.0 0.0 0.0"/>
            <inertia ixx="0.0" ixy="0.0" ixz="0.0" iyy="0.0" iyz="0.0" izz="0.0"/>
        </inertial>
    </link>

    <link name="plate">
        <visual>
            <geometry>
                <mesh filename="/home/daniel/dev/kuka_iiwa7_ros2/src/iiwa_description/resource/meshes/gripper/plate.stl"/>
            </geometry>
            <material name="alum_plastic">
                <color rgba="0.7 0.7 0.7 1.0"/>
            </material>
        </visual>
        <collision>
            <geometry>
                <mesh filename="/home/daniel/dev/kuka_iiwa7_ros2/src/iiwa_description/resource/meshes/gripper/plate.stl"/>
            </geometry>
        </collision>
        <inertial>
            <mass value="0.0"/>
            <origin xyz="0.0 0.0 0.0" rpy="0.0 0.0 0.0"/>
            <inertia ixx="0.0" ixy="0.0" ixz="0.0" iyy="0.0" iyz="0.0" izz="0.0"/>
        </inertial>
    </link>

    <link name="screw">
        <inertial>
            <origin xyz="0.0 0.0 0.0" rpy="0.0 0.0 0.0"/>
            <mass value="0.0"/>
            <inertia ixx="0.0" ixy="0.0" ixz="0.0" iyy="0.0" iyz="0.0" izz="0.0"/>
        </inertial>
        <visual name="">
            <origin xyz="0.0 0.0 0.0" rpy="0.0 0.0 0.0"/>
            <geometry>
                <mesh filename="/home/daniel/dev/kuka_iiwa7_ros2/src/iiwa_description/resource/meshes/gripper/screw.stl"/>
            </geometry>
            <material name="alum_plastic">
                <color rgba="0.7 0.7 0.7 1.0"/>
            </material>
        </visual>
    </link>


    <link name="finger1">
        <inertial>
            <origin xyz="0.0 0.0 0.0" rpy="0.0 0.0 0.0"/>
            <mass value="0.0"/>
            <inertia ixx="0.0" ixy="0.0" ixz="0.0" iyy="0.0" iyz="0.0" izz="0.0"/>
        </inertial>
        <visual name="">
            <origin xyz="9 -25 5" rpy="0.0 -1.57 0.0"/>
            <geometry>
                <mesh filename="/home/daniel/dev/kuka_iiwa7_ros2/src/iiwa_description/resource/meshes/gripper/finger_plates.stl"/>
            </geometry>
            <material name="">
                <color rgba="0.0 0.8 1.0 1.0"/>
            </material>
        </visual>
        <collision>
            <origin xyz="9 -25 5" rpy="0.0 -1.57 0.0"/>
            <geometry>
                <mesh filename="/home/daniel/dev/kuka_iiwa7_ros2/src/iiwa_description/resource/meshes/gripper/finger_plates.stl"/>
            </geometry>
        </collision>
    </link>

    <link name="finger2">
        <inertial>
            <origin xyz="0.0 0.0 0.0" rpy="0.0 0.0 0.0"/>
            <mass value="0.0"/>
            <inertia ixx="0.0" ixy="0.0" ixz="0.0" iyy="0.0" iyz="0.0" izz="0.0"/>
        </inertial>
        <visual name="">
            <origin xyz="9 -25 5" rpy="0.0 -1.57 0.0"/>
            <geometry>
                <mesh filename="/home/daniel/dev/kuka_iiwa7_ros2/src/iiwa_description/resource/meshes/gripper/finger_plates.stl"/>
            </geometry>
            <material name="">
                <color rgba="0.0 0.8 1.0 1.0"/>
            </material>
        </visual>
        <collision>
            <origin xyz="9 -25 5" rpy="0.0 -1.57 0.0"/>
            <geometry>
                <mesh filename="/home/daniel/dev/kuka_iiwa7_ros2/src/iiwa_description/resource/meshes/gripper/finger_plates.stl"/>
            </geometry>
        </collision>
    </link>

    <link name="finger3">
        <inertial>
            <origin xyz="0.0 0.0 0.0" rpy="0.0 0.0 0.0"/>
            <mass value="0.0"/>
            <inertia ixx="0.0" ixy="0.0" ixz="0.0" iyy="0.0" iyz="0.0" izz="0.0"/>
        </inertial>
        <visual name="">
            <origin xyz="9 -25 5" rpy="0.0 -1.57 0.0"/>
            <geometry>
                <mesh filename="/home/daniel/dev/kuka_iiwa7_ros2/src/iiwa_description/resource/meshes/gripper/finger_plates.stl"/>
            </geometry>
            <material name="">
                <color rgba="0.0 0.8 1.0 1.0"/>
            </material>
        </visual>
        <collision>
            <origin xyz="9 -25 5" rpy="0.0 -1.57 0.0"/>
            <geometry>
                <mesh filename="/home/daniel/dev/kuka_iiwa7_ros2/src/iiwa_description/resource/meshes/gripper/finger_plates.stl"/>
            </geometry>
        </collision>
    </link>

    <joint name="base" type="fixed">
        <origin xyz="0.0 0.0 61.3" rpy="0.0 0.0 0.0"/>
        <parent link="base_frame"/>
        <child link="plate"/>
    </joint>

    <joint name="base_screw" type="prismatic">
        <origin xyz="0.0 0.0 72" rpy="0.0 0.0 0.0"/>
        <parent link="base_frame"/>
        <child link="screw"/>
        <axis xyz="0.0 0.0 1"/>
        <limit lower="-7" upper="0.0" effort="0.0" velocity="0.0"/>
    </joint>

    <joint name="finger1_joint" type="revolute">
        <origin xyz="31.5 -18.5 28" rpy="0.0 0.0 -2.12"/>
        <parent link="plate"/>
        <child link="finger1"/>
        <axis xyz="1 0.0 0"/>
        <limit lower="-0.2" upper="0.07" effort="0.0" velocity="0.0"/>
        <mimic joint="base_screw" multiplier="-0.05" offset="-0.2"/>
    </joint>

    <joint name="finger2_joint" type="revolute">
        <origin xyz="-31.5 -18.5 28" rpy="0.0 0.0 2.12"/>
        <parent link="plate"/>
        <child link="finger2"/>
        <axis xyz="1 0.0 0"/>
        <limit lower="-0.2" upper="0.07" effort="0.0" velocity="0.0"/>
        <mimic joint="base_screw" multiplier="-0.05" offset="-0.2"/>
    </joint>

    <joint name="finger3_joint" type="revolute">
        <origin xyz="0 37 28" rpy="0.0 0.0 0.0"/>
        <parent link="plate"/>
        <child link="finger3"/>
        <axis xyz="1 0.0 0"/>
        <limit lower="-0.2" upper="0.07" effort="0.0" velocity="0.0"/>
        <mimic joint="base_screw" multiplier="-0.05" offset="-0.2"/>
    </joint>

</robot>
