<?xml version="1.0"?>
<robot xmlns:xacro="http://www.ros.org/wiki/xacro" xacro:version="1.0">

    <xacro:macro name="gripper_link"
                 params="name mass
                         ixx ixy ixz iyy iyz izz xyz_iner
                         mesh visual_xyz visual_rpy
                         r g b a">
        <link name="${name}">
            <inertial>
                <origin xyz="${xyz_iner}" rpy="0 0 0"/>
                <mass value="${mass}"/>
                <inertia ixx="${ixx}" ixy="${ixy}" ixz="${ixz}"
                         iyy="${iyy}" iyz="${iyz}" izz="${izz}"/>
            </inertial>
            <visual>
                <origin xyz="${visual_xyz}" rpy="${visual_rpy}"/>
                <geometry>
                    <mesh filename="${mesh}" scale="0.001 0.001 0.001"/>
                </geometry>
                <material name="${name}_material">
                    <color rgba="${r} ${g} ${b} ${a}"/>
                </material>
            </visual>
            <collision>
                <origin xyz="${visual_xyz}" rpy="${visual_rpy}"/>
                <geometry>
                    <mesh filename="${mesh}" scale="0.001 0.001 0.001"/>
                </geometry>
            </collision>
        </link>

        <gazebo reference="${name}">
            <visual>
                <material>
                    <ambient>${r} ${g} ${b} ${a}</ambient>
                    <diffuse>${r} ${g} ${b} ${a}</diffuse>
                    <specular>0.3 0.3 0.3 1.0</specular>
                </material>
            </visual>
            <collision>
                <surface>
                    <friction>
                        <ode><mu>1.0</mu><mu2>1.0</mu2></ode>
                    </friction>
                    <contact>
                        <ode><kp>1000000.0</kp><kd>100.0</kd></ode>
                    </contact>
                </surface>
            </collision>
        </gazebo>
    </xacro:macro>

    <xacro:macro name="prismatic_joint"
                 params="jname parent child xyz rpy axis lower upper effort velocity">
        <joint name="${jname}" type="prismatic">
            <origin xyz="${xyz}" rpy="${rpy}"/>
            <parent link="${parent}"/>
            <child link="${child}"/>
            <axis xyz="${axis}"/>
            <limit lower="${lower}" upper="${upper}"
                   effort="${effort}" velocity="${velocity}"/>
            <dynamics damping="0.5" friction="0.1"/>
        </joint>
    </xacro:macro>

    <xacro:macro name="mimic_revolute_joint"
                 params="jname parent child xyz rpy axis
                         lower upper effort velocity damping
                         mimic_joint multiplier mimic_offset">
        <joint name="${jname}" type="revolute">
            <origin xyz="${xyz}" rpy="${rpy}"/>
            <parent link="${parent}"/>
            <child link="${child}"/>
            <axis xyz="${axis}"/>
            <limit lower="${lower}" upper="${upper}"
                   effort="${effort}" velocity="${velocity}"/>
            <dynamics damping="${damping}" friction="0.05"/>
            <mimic joint="${mimic_joint}"
                   multiplier="${multiplier}"
                   offset="${mimic_offset}"/>
        </joint>
    </xacro:macro>

</robot>